Workbook

Sheet Calcutta
A1: 2025 Twin Creeks Member Guest Player Auction
G3: Shootout Bonus Pool | J3: ='Payout Calc'!P7 -> 4015 | M3: Member | N3: Owner
I4: 1st | J4: ='Payout Calc'!P3 -> 2010 | M4: Brijalba, Rufus | N4: =VLOOKUP(M4,'Master Player List'!$C$2:$N$82,12,0) -> Brijalba, Rufus
I5: 2nd | J5: ='Payout Calc'!P4 -> 1205 | M5: Maples, Brent | N5: =VLOOKUP(M5,'Master Player List'!$C$2:$N$82,12,0) -> Maples, Brent
I6: 3rd | J6: ='Payout Calc'!P5 -> 800 | M6: Aghazadeh, Abdol | N6: =VLOOKUP(M6,'Master Player List'!$C$2:$N$82,12,0) -> Brymer, Cory
A9: Flight #1
A10: Team # | B10: Team HCP | C10: Member | D10: Guest | E10: Bid | F10: Member Owner
A11: 1 | B11: =IF('Master Player List'!$L3=1,'Master Player List'!$J3,"") -> +5.2 | C11: =IF('Master Player List'!L3=1,CONCATENATE('Master Player List'!C3," (",'Master Player List'!E3,")"),"") -> Brijalba, Rufus (+3.1) | D11: =IF('Master Player List'!L3=1,CONCATENATE('Master Player List'!F3," (",'Master Player List'!H3,")"),"") -> Peck, Colin (+2.1) | E11: 3200 | F11: Brijalba, Rufus | H11: Flight #1 Total | I11: =SUM(E11:E18) -> 20600 | M11: Day Money
A12: 2 | B12: =IF('Master Player List'!$L4=1,'Master Player List'!$J4,"") -> +0.7 | C12: =IF('Master Player List'!L4=1,CONCATENATE('Master Player List'!C4," (",'Master Player List'!E4,")"),"") -> Paschke, Michael (3.6) | D12: =IF('Master Player List'!L4=1,CONCATENATE('Master Player List'!F4," (",'Master Player List'!H4,")"),"") -> Montes, Daniel (+4.3) | E12: 4000 | F12: Edwards, Patric | H12: Flight Winners | O12: Thursday | Q12: Friday | S12: Saturday
A13: 3 | B13: =IF('Master Player List'!$L5=1,'Master Player List'!$J5,"") -> 0.1 | C13: =IF('Master Player List'!L5=1,CONCATENATE('Master Player List'!C5," (",'Master Player List'!E5,")"),"") -> Harwood, Michael (+0.5) | D13: =IF('Master Player List'!L5=1,CONCATENATE('Master Player List'!F5," (",'Master Player List'!H5,")"),"") -> Diaz, Gerry (0.6) | E13: 2200 | F13: Harwood, Michael | J13: Member | K13: Owner | O13: Member | P13: Owner | Q13: Member | R13: Owner | S13: Member | T13: Owner
A14: 4 | B14: =IF('Master Player List'!$L6=1,'Master Player List'!$J6,"") -> 1.8 | C14: =IF('Master Player List'!L6=1,CONCATENATE('Master Player List'!C6," (",'Master Player List'!E6,")"),"") -> Lambert, Jeff (0.5) | D14: =IF('Master Player List'!L6=1,CONCATENATE('Master Player List'!F6," (",'Master Player List'!H6,")"),"") -> White, Jason (1.3) | E14: 1900 | F14: Aghazadeh, Abdol | H14: ="1st (" & (TEXT('Payout Calc'!$K$4, "0%")) & ")" -> 1st (50%) | I14: ='Payout Calc'!D24 -> 6260 | J14: Lambert, Jeff | K14: =VLOOKUP(J14,'Master Player List'!$C$2:$N$82,12,0) -> Aghazadeh, Abdol | M14: ="1st (" & (TEXT('Payout Calc'!I4, "0%")) & ")" -> 1st (50%) | N14: ='Payout Calc'!D34 -> 1120 | O14: Brijalba, Rufus | P14: =VLOOKUP(O14,'Master Player List'!$C$2:$N$82,12,0) -> Brijalba, Rufus | Q14: Paschke, Michael | R14: =VLOOKUP(Q14,'Master Player List'!$C$2:$N$82,12,0) -> Edwards, Patric | S14: Paschke, Michael | T14: =VLOOKUP(S14,'Master Player List'!$C$2:$N$82,12,0) -> Edwards, Patric
A15: 5 | B15: =IF('Master Player List'!$L7=1,'Master Player List'!$J7,"") -> 2.9 | C15: =IF('Master Player List'!L7=1,CONCATENATE('Master Player List'!C7," (",'Master Player List'!E7,")"),"") -> Kim, Steven (2.8) | D15: =IF('Master Player List'!L7=1,CONCATENATE('Master Player List'!F7," (",'Master Player List'!H7,")"),"") -> Kerrigan, Mike (0.1) | E15: 1600 | F15: Godhania, Vikas | H15: ="2nd (" & (TEXT('Payout Calc'!$K$5, "0%")) & ")" -> 2nd (30%) | I15: ='Payout Calc'!D25 -> 3755 | J15: Harwood, Michael | K15: =VLOOKUP(J15,'Master Player List'!$C$2:$N$82,12,0) -> Harwood, Michael | M15: ="2nd (" & (TEXT('Payout Calc'!I5, "0%")) & ")" -> 2nd (30%) | N15: ='Payout Calc'!D35 -> 670 | O15: Kim, Steven | P15: =VLOOKUP(O15,'Master Player List'!$C$2:$N$82,12,0) -> Godhania, Vikas | Q15: Paschke, Michael | R15: =VLOOKUP(Q15,'Master Player List'!$C$2:$N$82,12,0) -> Edwards, Patric | S15: Kim, Steven | T15: =VLOOKUP(S15,'Master Player List'!$C$2:$N$82,12,0) -> Godhania, Vikas
A16: 6 | B16: =IF('Master Player List'!$L8=1,'Master Player List'!$J8,"") -> 3.8 | C16: =IF('Master Player List'!L8=1,CONCATENATE('Master Player List'!C8," (",'Master Player List'!E8,")"),"") -> Maples, Brent (+0.7) | D16: =IF('Master Player List'!L8=1,CONCATENATE('Master Player List'!F8," (",'Master Player List'!H8,")"),"") -> Buratto, Mark (4.5) | E16: 2500 | F16: Maples, Brent | H16: ="3rd (" & (TEXT('Payout Calc'!$K$6, "0%")) & ")" -> 3rd (20%) | I16: ='Payout Calc'!D26 -> 2505 | J16: Paschke, Michael | K16: =VLOOKUP(J16,'Master Player List'!$C$2:$N$82,12,0) -> Edwards, Patric | M16: ="3rd (" & (TEXT('Payout Calc'!I6, "0%")) & ")" -> 3rd (20%) | N16: ='Payout Calc'!D36 -> 445 | O16: Paschke, Michael | P16: =VLOOKUP(O16,'Master Player List'!$C$2:$N$82,12,0) -> Edwards, Patric | Q16: Paschke, Michael | R16: =VLOOKUP(Q16,'Master Player List'!$C$2:$N$82,12,0) -> Edwards, Patric | S16: Paschke, Michael | T16: =VLOOKUP(S16,'Master Player List'!$C$2:$N$82,12,0) -> Edwards, Patric
A17: 7 | B17: =IF('Master Player List'!$L9=1,'Master Player List'!$J9,"") -> 4.1 | C17: =IF('Master Player List'!L9=1,CONCATENATE('Master Player List'!C9," (",'Master Player List'!E9,")"),"") -> Darter, Bret (0.2) | D17: =IF('Master Player List'!L9=1,CONCATENATE('Master Player List'!F9," (",'Master Player List'!H9,")"),"") -> Caldwell, Trey (3.9) | E17: 2200 | F17: Darter, Bret
A18: 8 | B18: =IF('Master Player List'!$L10=1,'Master Player List'!$J10,"") -> 4.5 | C18: =IF('Master Player List'!L10=1,CONCATENATE('Master Player List'!C10," (",'Master Player List'!E10,")"),"") -> Black, Gene (3.1) | D18: =IF('Master Player List'!L10=1,CONCATENATE('Master Player List'!F10," (",'Master Player List'!H10,")"),"") -> Tilson, Scott (1.4) | E18: 3000 | F18: Vidrine, Scot
D19: Total
A20: Flight #2
A21: Team # | B21: Team HCP | C21: Member | D21: Guest | E21: Bid | F21: Member Owner
A22: 1 | B22: =IF('Master Player List'!$L11=2,'Master Player List'!$J11,"") -> 4.6 | C22: =IF('Master Player List'!L11=2,CONCATENATE('Master Player List'!C11," (",'Master Player List'!E11,")"),"") -> Lau, Jason (4.7) | D22: =IF('Master Player List'!L11=2,CONCATENATE('Master Player List'!F11," (",'Master Player List'!H11,")"),"") -> Martin, Aaron (+0.1) | E22: 2600 | F22: Brymer, Cory | H22: Flight #2 Total | I22: =SUM(E22:E29) -> 21000 | M22: Day Money
A23: 2 | B23: =IF('Master Player List'!$L12=2,'Master Player List'!$J12,"") -> 5 | C23: =IF('Master Player List'!L12=2,CONCATENATE('Master Player List'!C12," (",'Master Player List'!E12,")"),"") -> Peterson, Erik (0) | D23: =IF('Master Player List'!L12=2,CONCATENATE('Master Player List'!F12," (",'Master Player List'!H12,")"),"") -> Ferrell, Ryan (5) | E23: 2200 | F23: Aghazadeh, Abdol | H23: Flight Winners | O23: Thursday | Q23: Friday | S23: Saturday
A24: 3 | B24: =IF('Master Player List'!$L13=2,'Master Player List'!$J13,"") -> 5.1 | C24: =IF('Master Player List'!L13=2,CONCATENATE('Master Player List'!C13," (",'Master Player List'!E13,")"),"") -> Fulmer, Austen (+3.4) | D24: =IF('Master Player List'!L13=2,CONCATENATE('Master Player List'!F13," (",'Master Player List'!H13,")"),"") -> Pacheco, Jeremy (8.5) | E24: 2800 | F24: Aghazadeh, Abdol | J24: Member | K24: Owner | O24: Member | P24: Owner | Q24: Member | R24: Owner | S24: Member | T24: Owner
A25: 4 | B25: =IF('Master Player List'!$L14=2,'Master Player List'!$J14,"") -> 6 | C25: =IF('Master Player List'!L14=2,CONCATENATE('Master Player List'!C14," (",'Master Player List'!E14,")"),"") -> Escobar, Rafael (1.5) | D25: =IF('Master Player List'!L14=2,CONCATENATE('Master Player List'!F14," (",'Master Player List'!H14,")"),"") -> Gillmor, Rob (4.5) | E25: 1800 | F25: Bohnen, John | H25: ="1st (" & (TEXT('Payout Calc'!$K$4, "0%")) & ")" -> 1st (50%) | I25: ='Payout Calc'!H24 -> 6380 | J25: Sherman, Michael | K25: =VLOOKUP(J25,'Master Player List'!$C$2:$N$82,12,0) -> Brymer, Cory | M25: ="1st (" & (TEXT('Payout Calc'!I4, "0%")) & ")" -> 1st (50%) | N25: ='Payout Calc'!H34 -> 1145 | O25: Escobar, Rafael | P25: =VLOOKUP(O25,'Master Player List'!$C$2:$N$82,12,0) -> Bohnen, John | R25: =VLOOKUP(Q25,'Master Player List'!$C$2:$N$82,12,0) -> #N/A | S25: Sherman, Michael | T25: =VLOOKUP(S25,'Master Player List'!$C$2:$N$82,12,0) -> Brymer, Cory
A26: 5 | B26: =IF('Master Player List'!$L15=2,'Master Player List'!$J15,"") -> 6.1 | C26: =IF('Master Player List'!L15=2,CONCATENATE('Master Player List'!C15," (",'Master Player List'!E15,")"),"") -> Bellomio, Ron (3.2) | D26: =IF('Master Player List'!L15=2,CONCATENATE('Master Player List'!F15," (",'Master Player List'!H15,")"),"") -> Boles, John (2.9) | E26: 3000 | F26: Bellomio, Ron | H26: ="2nd (" & (TEXT('Payout Calc'!$K$5, "0%")) & ")" -> 2nd (30%) | I26: ='Payout Calc'!H25 -> 3830 | J26: Fulmer, Austen | K26: =VLOOKUP(J26,'Master Player List'!$C$2:$N$82,12,0) -> Aghazadeh, Abdol | M26: ="2nd (" & (TEXT('Payout Calc'!I5, "0%")) & ")" -> 2nd (30%) | N26: ='Payout Calc'!H35 -> 685 | O26: Sherman, Michael | P26: =VLOOKUP(O26,'Master Player List'!$C$2:$N$82,12,0) -> Brymer, Cory | Q26: Bellomio, Ron | R26: =VLOOKUP(Q26,'Master Player List'!$C$2:$N$82,12,0) -> Bellomio, Ron | S26: Purslow, Brock | T26: =VLOOKUP(S26,'Master Player List'!$C$2:$N$82,12,0) -> Drain, Zip
A27: 6 | B27: =IF('Master Player List'!$L16=2,'Master Player List'!$J16,"") -> 6.6 | C27: =IF('Master Player List'!L16=2,CONCATENATE('Master Player List'!C16," (",'Master Player List'!E16,")"),"") -> Vaughn, Earl (2.9) | D27: =IF('Master Player List'!L16=2,CONCATENATE('Master Player List'!F16," (",'Master Player List'!H16,")"),"") -> Cowden, Cole (3.7) | E27: 5000 | F27: Godhania, Vikas | H27: ="3rd (" & (TEXT('Payout Calc'!$K$6, "0%")) & ")" -> 3rd (20%) | I27: ='Payout Calc'!H26 -> 2550 | J27: Lau, Jason | K27: =VLOOKUP(J27,'Master Player List'!$C$2:$N$82,12,0) -> Brymer, Cory | M27: ="3rd (" & (TEXT('Payout Calc'!I6, "0%")) & ")" -> 3rd (20%) | N27: ='Payout Calc'!H36 -> 455 | O27: Peterson, Erik | P27: =VLOOKUP(O27,'Master Player List'!$C$2:$N$82,12,0) -> Aghazadeh, Abdol | Q27: Sherman, Michael | R27: =VLOOKUP(Q27,'Master Player List'!$C$2:$N$82,12,0) -> Brymer, Cory | T27: =VLOOKUP(S27,'Master Player List'!$C$2:$N$82,12,0) -> #N/A
A28: 7 | B28: =IF('Master Player List'!$L17=2,'Master Player List'!$J17,"") -> 7.5 | C28: =IF('Master Player List'!L17=2,CONCATENATE('Master Player List'!C17," (",'Master Player List'!E17,")"),"") -> Jain, Nitin (7.5) | D28: =IF('Master Player List'!L17=2,CONCATENATE('Master Player List'!F17," (",'Master Player List'!H17,")"),"") -> Friggle, Scott (0) | E28: 1200 | F28: Wedgeworth, Cliff
A29: 8 | B29: =IF('Master Player List'!$L18=2,'Master Player List'!$J18,"") -> 7.6 | C29: =IF('Master Player List'!L18=2,CONCATENATE('Master Player List'!C18," (",'Master Player List'!E18,")"),"") -> Purslow, Brock (0) | D29: =IF('Master Player List'!L18=2,CONCATENATE('Master Player List'!F18," (",'Master Player List'!H18,")"),"") -> Thompson, Brad (7.6) | E29: 2400 | F29: Drain, Zip
D30: Total | E30: =SUM(E22:E29) -> 21000
A31: Flight #3
A32: Team # | B32: Team HCP | C32: Member | D32: Guest | E32: Bid | F32: Member Owner
A33: 1 | B33: =IF('Master Player List'!L19=3,'Master Player List'!I19,"") -> 8.8 | C33: =IF('Master Player List'!L19=3,CONCATENATE('Master Player List'!C19," (",'Master Player List'!E19,")"),"") -> Esau, Nickolai (+1) | D33: =IF('Master Player List'!L19=3,CONCATENATE('Master Player List'!F19," (",'Master Player List'!H19,")"),"") -> Esau, Rex (9.8) | E33: 1100 | F33: Bohnen, John | H33: Flight #3 Total | I33: =SUM(E33:E40) -> 13400 | M33: Day Money
A34: 2 | B34: =IF('Master Player List'!L20=3,'Master Player List'!I20,"") -> 9 | C34: =IF('Master Player List'!L20=3,CONCATENATE('Master Player List'!C20," (",'Master Player List'!E20,")"),"") -> Scott, Jonathan (2.4) | D34: =IF('Master Player List'!L20=3,CONCATENATE('Master Player List'!F20," (",'Master Player List'!H20,")"),"") -> McGowan, Marshall (6.6) | E34: 1100 | F34: Scott, Jonathan | H34: Flight Winners | O34: Thursday | Q34: Friday | S34: Saturday
A35: 3 | B35: =IF('Master Player List'!L21=3,'Master Player List'!I21,"") -> 9.1 | C35: =IF('Master Player List'!L21=3,CONCATENATE('Master Player List'!C21," (",'Master Player List'!E21,")"),"") -> Hill, Justin (9.2) | D35: =IF('Master Player List'!L21=3,CONCATENATE('Master Player List'!F21," (",'Master Player List'!H21,")"),"") -> Bobbitt, Jason (+0.1) | E35: 1900 | F35: Vidrine, Scot | J35: Member | K35: Owner | O35: Member | P35: Owner | Q35: Member | R35: Owner | S35: Member | T35: Owner
A36: 4 | B36: =IF('Master Player List'!L22=3,'Master Player List'!I22,"") -> 9.2 | C36: =IF('Master Player List'!L22=3,CONCATENATE('Master Player List'!C22," (",'Master Player List'!E22,")"),"") -> Ramirez, David (3.5) | D36: =IF('Master Player List'!L22=3,CONCATENATE('Master Player List'!F22," (",'Master Player List'!H22,")"),"") -> May, Jason (5.7) | E36: 2100 | F36: Aghazadeh, Abdol | H36: ="1st (" & (TEXT('Payout Calc'!$K$4, "0%")) & ")" -> 1st (50%) | I36: ='Payout Calc'!L24 -> 4060 | K36: =VLOOKUP(J36,'Master Player List'!$C$2:$N$82,12,0) -> #N/A | M36: ="1st (" & (TEXT('Payout Calc'!$I$4, "0%")) & ")" -> 1st (50%) | N36: ='Payout Calc'!L34 -> 725 | P36: =VLOOKUP(O36,'Master Player List'!$C$2:$N$82,12,0) -> #N/A | R36: =VLOOKUP(Q36,'Master Player List'!$C$2:$N$82,12,0) -> #N/A | T36: =VLOOKUP(S36,'Master Player List'!$C$2:$N$82,12,0) -> #N/A
A37: 5 | B37: =IF('Master Player List'!L23=3,'Master Player List'!I23,"") -> 9.5 | C37: =IF('Master Player List'!L23=3,CONCATENATE('Master Player List'!C23," (",'Master Player List'!E23,")"),"") -> Kellner, Timothy (1.5) | D37: =IF('Master Player List'!L23=3,CONCATENATE('Master Player List'!F23," (",'Master Player List'!H23,")"),"") -> Flinn, Kyle (8) | E37: 2100 | F37: Vaughn, Earl | H37: ="2nd (" & (TEXT('Payout Calc'!$K$5, "0%")) & ")" -> 2nd (30%) | I37: ='Payout Calc'!L25 -> 2435 | J37: Hill, Justin | K37: =VLOOKUP(J37,'Master Player List'!$C$2:$N$82,12,0) -> Vidrine, Scot | M37: ="2nd (" & (TEXT('Payout Calc'!$I$5, "0%")) & ")" -> 2nd (30%) | N37: ='Payout Calc'!L35 -> 435 | P37: =VLOOKUP(O37,'Master Player List'!$C$2:$N$82,12,0) -> #N/A | R37: =VLOOKUP(Q37,'Master Player List'!$C$2:$N$82,12,0) -> #N/A | T37: =VLOOKUP(S37,'Master Player List'!$C$2:$N$82,12,0) -> #N/A
A38: 6 | B38: =IF('Master Player List'!L24=3,'Master Player List'!I24,"") -> 9.7 | C38: =IF('Master Player List'!L24=3,CONCATENATE('Master Player List'!C24," (",'Master Player List'!E24,")"),"") -> Kromis, Daniel (4.5) | D38: =IF('Master Player List'!L24=3,CONCATENATE('Master Player List'!F24," (",'Master Player List'!H24,")"),"") -> Wilson, David (5.2) | E38: 1800 | F38: Kromis, Daniel | H38: ="3rd (" & (TEXT('Payout Calc'!$K$6, "0%")) & ")" -> 3rd (20%) | I38: ='Payout Calc'!L26 -> 1625 | K38: =VLOOKUP(J38,'Master Player List'!$C$2:$N$82,12,0) -> #N/A | M38: ="3rd (" & (TEXT('Payout Calc'!$I$6, "0%")) & ")" -> 3rd (20%) | N38: ='Payout Calc'!L36 -> 290 | O38: Scott, Jonathan | P38: =VLOOKUP(O38,'Master Player List'!$C$2:$N$82,12,0) -> Scott, Jonathan | R38: =VLOOKUP(Q38,'Master Player List'!$C$2:$N$82,12,0) -> #N/A | T38: =VLOOKUP(S38,'Master Player List'!$C$2:$N$82,12,0) -> #N/A
A39: 7 | B39: =IF('Master Player List'!L25=3,'Master Player List'!I25,"") -> 10.3 | C39: =IF('Master Player List'!L25=3,CONCATENATE('Master Player List'!C25," (",'Master Player List'!E25,")"),"") -> Sherman, Michael (7.5) | D39: =IF('Master Player List'!L25=3,CONCATENATE('Master Player List'!F25," (",'Master Player List'!H25,")"),"") -> Elvers, Nate (2.8) | E39: 1900 | F39: Brymer, Cory
A40: 8 | B40: =IF('Master Player List'!L26=3,'Master Player List'!I26,"") -> 10.3 | C40: =IF('Master Player List'!L26=3,CONCATENATE('Master Player List'!C26," (",'Master Player List'!E26,")"),"") -> Jones, Jason (4.9) | D40: =IF('Master Player List'!L26=3,CONCATENATE('Master Player List'!F26," (",'Master Player List'!H26,")"),"") -> Qualls, Michael (5.4) | E40: 1400 | F40: Fulmer, Austen
D41: Total | E41: =SUM(E33:E40) -> 13400
A42: Flight #4
A43: Team # | B43: Team HCP | C43: Member | D43: Guest | E43: Bid | F43: Member Owner
...

Sheet Team Sheet
B1: Member | C1: Guest
A2: # | B2: Player 1 hndcp | C2: Player 2 hndcp
B3: Jerry Conwell ACP 2.5 | C3: Ken Duemig
A4: 1
B5: Chris Cannatti ACP 3.6 | C5: Kevin Spradling
A6: 2
B7: Bret Darter 5/31 0.6 | C7: Kyle Flinn
A8: 3
B9: Aaron Gouldie 1/31 11.0 | C9: Adam Gouldie
A10: 4
B11: Tony Montaleone 4.6 | C11: Robert Lemon
A12: 5
B13: Juan Munoz 6.1 | C13: Bert Sanchez
A14: 6
B15: Brian Blumentrath ACP 3.5 | C15: Adam Gafken
A16: 7
B17: Valente Quintana ACP 5.9 | C17: Antonio Asali
A18: 8
B19: Kyle Krueger | C19: Christopher Graham
A20: 9
B21: Blake Korndorffer 0.8 | C21: Ryan Pavlu
A22: 10
B23: Tim Kellner 2.8 | C23: Michael Garcia
A24: 11
B25: Evan Ediger ACP | C25: Chris Berrean
A26: 12
B27: Mark Grantham | C27: Stuart Shaw
A28: 13
B29: Chris Toombs 1231 | C29: Dennis Toombs
A30: 14
B31: Tyler Nelson 5.2 | C31: Bob Nelson
A32: 15
B33: David Barrera 8.2 | C33: John Hennessy
A34: 16
B35: Kevin Richgels 4/30 | C35: Chad Brennan
A36: 17
B37: Matthew Herrick ACP 6.4 | C37: Scott Vidrine
A38: 18
B39: Ryan Gromfin 1.6 | C39: Jeremy Moreno
A40: 19
...

Sheet Master Player List
B2: Team # | C2: Member | D2: Course Handicap | E2: Handicap Formatted | F2: Guest | G2: Course Handicap | H2: Handicap Formatted | I2: Team Handicap | J2: Team Handicap Formatted | K2: Handicap Differential | L2: Flight | M2: Team # | N2: Member Owner
B3: 1 | C3: Brijalba, Rufus | D3: -3.1 | E3: =IF(((D3)<0),"+"&D3*(-1)&"",D3) -> +3.1 | F3: Peck, Colin | G3: -2.1 | H3: =IF(((G3)<0),"+"&G3*(-1)&"",G3) -> +2.1 | I3: =D3+G3 -> -5.2 | J3: =IF(((I3)<0),"+"&I3*(-1)&"",I3) -> +5.2 | K3: =ABS(D3-G3) -> 1 | L3: 1 | M3: 1 | N3: =IF(ISTEXT(C3), Calcutta!F11, "") -> Brijalba, Rufus
B4: 2 | C4: Paschke, Michael | D4: 3.6 | E4: =IF(((D4)<0),"+"&D4*(-1)&"",D4) -> 3.6 | F4: Montes, Daniel | G4: -4.3 | H4: =IF(((G4)<0),"+"&G4*(-1)&"",G4) -> +4.3 | I4: =D4+G4 -> -0.7 | J4: =IF(((I4)<0),"+"&I4*(-1)&"",I4) -> +0.7 | K4: =ABS(D4-G4) -> 7.9 | L4: 1 | M4: 2 | N4: =IF(ISTEXT(C4), Calcutta!F12, "") -> Edwards, Patric
B5: 3 | C5: Harwood, Michael | D5: -0.5 | E5: =IF(((D5)<0),"+"&D5*(-1)&"",D5) -> +0.5 | F5: Diaz, Gerry | G5: 0.6 | H5: =IF(((G5)<0),"+"&G5*(-1)&"",G5) -> 0.6 | I5: =D5+G5 -> 0.1 | J5: =IF(((I5)<(-1)),"+"&I5*(-1)&"",I5) -> 0.1 | K5: =ABS(D5-G5) -> 1.1 | L5: 1 | M5: 3 | N5: =IF(ISTEXT(C5), Calcutta!F13, "") -> Harwood, Michael | R5: Total Teams | T5: =COUNTA(C3:C82) -> 80
B6: 4 | C6: Lambert, Jeff | D6: 0.5 | E6: =IF(((D6)<0),"+"&D6*(-1)&"",D6) -> 0.5 | F6: White, Jason | G6: 1.3 | H6: =IF(((G6)<0),"+"&G6*(-1)&"",G6) -> 1.3 | I6: =D6+G6 -> 1.8 | J6: =IF((I6<0),"+"&I6*(-1)&"",I6) -> 1.8 | K6: =ABS(D6-G6) -> 0.8 | L6: 1 | M6: 4 | N6: =IF(ISTEXT(C6), Calcutta!F14, "") -> Aghazadeh, Abdol | R6: Teams per Flight (10 flights) | T6: =T5/10 -> 8
B7: 5 | C7: Kim, Steven | D7: 2.8 | E7: =IF(((D7)<0),"+"&D7*(-1)&"",D7) -> 2.8 | F7: Kerrigan, Mike | G7: 0.1 | H7: =IF(((G7)<0),"+"&G7*(-1)&"",G7) -> 0.1 | I7: =D7+G7 -> 2.9 | J7: =IF((I7<0),"+"&I7*(-1)&"",I7) -> 2.9 | K7: =ABS(D7-G7) -> 2.7 | L7: 1 | M7: 5 | N7: =IF(ISTEXT(C7), Calcutta!F15, "") -> Godhania, Vikas
B8: 6 | C8: Maples, Brent | D8: -0.7 | E8: =IF(((D8)<0),"+"&D8*(-1)&"",D8) -> +0.7 | F8: Buratto, Mark | G8: 4.5 | H8: =IF(((G8)<0),"+"&G8*(-1)&"",G8) -> 4.5 | I8: =D8+G8 -> 3.8 | J8: =IF((I8<0),"+"&I8*(-1)&"",I8) -> 3.8 | K8: =ABS(D8-G8) -> 5.2 | L8: 1 | M8: 6 | N8: =IF(ISTEXT(C8), Calcutta!F16, "") -> Maples, Brent
B9: 7 | C9: Darter, Bret | D9: 0.2 | E9: =IF(((D9)<0),"+"&D9*(-1)&"",D9) -> 0.2 | F9: Caldwell, Trey | G9: 3.9 | H9: =IF(((G9)<0),"+"&G9*(-1)&"",G9) -> 3.9 | I9: =D9+G9 -> 4.1 | J9: =IF((I9<0),"+"&I9*(-1)&"",I9) -> 4.1 | K9: =ABS(D9-G9) -> 3.7 | L9: 1 | M9: 7 | N9: =IF(ISTEXT(C9), Calcutta!F17, "") -> Darter, Bret
B10: 8 | C10: Black, Gene | D10: 3.1 | E10: =IF(((D10)<0),"+"&D10*(-1)&"",D10) -> 3.1 | F10: Tilson, Scott | G10: 1.4 | H10: =IF(((G10)<0),"+"&G10*(-1)&"",G10) -> 1.4 | I10: =D10+G10 -> 4.5 | J10: =IF((I10<0),"+"&I10*(-1)&"",I10) -> 4.5 | K10: =ABS(D10-G10) -> 1.7 | L10: 1 | M10: 8 | N10: =IF(ISTEXT(C10), Calcutta!F18, "") -> Vidrine, Scot
B11: 9 | C11: Lau, Jason | D11: 4.7 | E11: =IF(((D11)<0),"+"&D11*(-1)&"",D11) -> 4.7 | F11: Martin, Aaron | G11: -0.1 | H11: =IF(((G11)<0),"+"&G11*(-1)&"",G11) -> +0.1 | I11: =D11+G11 -> 4.6 | J11: =IF((I11<0),"+"&I11*(-1)&"",I11) -> 4.6 | K11: =ABS(D11-G11) -> 4.8 | L11: 2 | M11: 1 | N11: =IF(ISTEXT(C11), Calcutta!F22, "") -> Brymer, Cory
B12: 10 | C12: Peterson, Erik | D12: 0 | E12: =IF(((D12)<0),"+"&D12*(-1)&"",D12) -> 0 | F12: Ferrell, Ryan | G12: 5 | H12: =IF(((G12)<0),"+"&G12*(-1)&"",G12) -> 5 | I12: =D12+G12 -> 5 | J12: =IF((I12<0),"+"&I12*(-1)&"",I12) -> 5 | K12: =ABS(D12-G12) -> 5 | L12: 2 | M12: 2 | N12: =IF(ISTEXT(C12), Calcutta!F23, "") -> Aghazadeh, Abdol
B13: 11 | C13: Fulmer, Austen | D13: -3.4 | E13: =IF(((D13)<0),"+"&D13*(-1)&"",D13) -> +3.4 | F13: Pacheco, Jeremy | G13: 8.5 | H13: =IF(((G13)<0),"+"&G13*(-1)&"",G13) -> 8.5 | I13: =D13+G13 -> 5.1 | J13: =IF((I13<0),"+"&I13*(-1)&"",I13) -> 5.1 | K13: =ABS(D13-G13) -> 11.9 | L13: 2 | M13: 3 | N13: =IF(ISTEXT(C13), Calcutta!F24, "") -> Aghazadeh, Abdol
B14: 12 | C14: Escobar, Rafael | D14: 1.5 | E14: =IF(((D14)<0),"+"&D14*(-1)&"",D14) -> 1.5 | F14: Gillmor, Rob | G14: 4.5 | H14: =IF(((G14)<0),"+"&G14*(-1)&"",G14) -> 4.5 | I14: =D14+G14 -> 6 | J14: =IF((I14<0),"+"&I14*(-1)&"",I14) -> 6 | K14: =ABS(D14-G14) -> 3 | L14: 2 | M14: 4 | N14: =IF(ISTEXT(C14), Calcutta!F25, "") -> Bohnen, John
B15: 13 | C15: Bellomio, Ron | D15: 3.2 | E15: =IF(((D15)<0),"+"&D15*(-1)&"",D15) -> 3.2 | F15: Boles, John | G15: 2.9 | H15: =IF(((G15)<0),"+"&G15*(-1)&"",G15) -> 2.9 | I15: =D15+G15 -> 6.1 | J15: =IF((I15<0),"+"&I15*(-1)&"",I15) -> 6.1 | K15: =ABS(D15-G15) -> 0.3 | L15: 2 | M15: 5 | N15: =IF(ISTEXT(C15), Calcutta!F26, "") -> Bellomio, Ron
B16: 14 | C16: Vaughn, Earl | D16: 2.9 | E16: =IF(((D16)<0),"+"&D16*(-1)&"",D16) -> 2.9 | F16: Cowden, Cole | G16: 3.7 | H16: =IF(((G16)<0),"+"&G16*(-1)&"",G16) -> 3.7 | I16: =D16+G16 -> 6.6 | J16: =IF((I16<0),"+"&I16*(-1)&"",I16) -> 6.6 | K16: =ABS(D16-G16) -> 0.8 | L16: 2 | M16: 6 | N16: =IF(ISTEXT(C16), Calcutta!F27, "") -> Godhania, Vikas
B17: 15 | C17: Jain, Nitin | D17: 7.5 | E17: =IF(((D17)<0),"+"&D17*(-1)&"",D17) -> 7.5 | F17: Friggle, Scott | G17: 0 | H17: =IF(((G17)<0),"+"&G17*(-1)&"",G17) -> 0 | I17: =D17+G17 -> 7.5 | J17: =IF((I17<0),"+"&I17*(-1)&"",I17) -> 7.5 | K17: =ABS(D17-G17) -> 7.5 | L17: 2 | M17: 7 | N17: =IF(ISTEXT(C17), Calcutta!F28, "") -> Wedgeworth, Cliff
B18: 16 | C18: Purslow, Brock | D18: 0 | E18: =IF(((D18)<0),"+"&D18*(-1)&"",D18) -> 0 | F18: Thompson, Brad | G18: 7.6 | H18: =IF(((G18)<0),"+"&G18*(-1)&"",G18) -> 7.6 | I18: =D18+G18 -> 7.6 | J18: =IF((I18<0),"+"&I18*(-1)&"",I18) -> 7.6 | K18: =ABS(D18-G18) -> 7.6 | L18: 2 | M18: 8 | N18: =IF(ISTEXT(C18), Calcutta!F29, "") -> Drain, Zip
B19: 17 | C19: Esau, Nickolai | D19: -1 | E19: =IF(((D19)<0),"+"&D19*(-1)&"",D19) -> +1 | F19: Esau, Rex | G19: 9.8 | H19: =IF(((G19)<0),"+"&G19*(-1)&"",G19) -> 9.8 | I19: =D19+G19 -> 8.8 | J19: =IF((I19<0),"+"&I19*(-1)&"",I19) -> 8.8 | K19: =ABS(D19-G19) -> 10.8 | L19: 3 | M19: 1 | N19: =IF(ISTEXT(C19), Calcutta!F33, "") -> Bohnen, John
B20: 18 | C20: Scott, Jonathan | D20: 2.4 | E20: =IF(((D20)<0),"+"&D20*(-1)&"",D20) -> 2.4 | F20: McGowan, Marshall | G20: 6.6 | H20: =IF(((G20)<0),"+"&G20*(-1)&"",G20) -> 6.6 | I20: =D20+G20 -> 9 | J20: =IF((I20<0),"+"&I20*(-1)&"",I20) -> 9 | K20: =ABS(D20-G20) -> 4.2 | L20: 3 | M20: 2 | N20: =IF(ISTEXT(C20), Calcutta!F34, "") -> Scott, Jonathan
B21: 19 | C21: Hill, Justin | D21: 9.2 | E21: =IF(((D21)<0),"+"&D21*(-1)&"",D21) -> 9.2 | F21: Bobbitt, Jason | G21: -0.1 | H21: =IF(((G21)<0),"+"&G21*(-1)&"",G21) -> +0.1 | I21: =D21+G21 -> 9.1 | J21: =IF((I21<0),"+"&I21*(-1)&"",I21) -> 9.1 | K21: =ABS(D21-G21) -> 9.3 | L21: 3 | M21: 3 | N21: =IF(ISTEXT(C21), Calcutta!F35, "") -> Vidrine, Scot
B22: 20 | C22: Ramirez, David | D22: 3.5 | E22: =IF(((D22)<0),"+"&D22*(-1)&"",D22) -> 3.5 | F22: May, Jason | G22: 5.7 | H22: =IF(((G22)<0),"+"&G22*(-1)&"",G22) -> 5.7 | I22: =D22+G22 -> 9.2 | J22: =IF((I22<0),"+"&I22*(-1)&"",I22) -> 9.2 | K22: =ABS(D22-G22) -> 2.2 | L22: 3 | M22: 4 | N22: =IF(ISTEXT(C22), Calcutta!F36, "") -> Aghazadeh, Abdol
B23: 21 | C23: Kellner, Timothy | D23: 1.5 | E23: =IF(((D23)<0),"+"&D23*(-1)&"",D23) -> 1.5 | F23: Flinn, Kyle | G23: 8 | H23: =IF(((G23)<0),"+"&G23*(-1)&"",G23) -> 8 | I23: =D23+G23 -> 9.5 | J23: =IF((I23<0),"+"&I23*(-1)&"",I23) -> 9.5 | K23: =ABS(D23-G23) -> 6.5 | L23: 3 | M23: 5 | N23: =IF(ISTEXT(C23), Calcutta!F37, "") -> Vaughn, Earl
B24: 22 | C24: Kromis, Daniel | D24: 4.5 | E24: =IF(((D24)<0),"+"&D24*(-1)&"",D24) -> 4.5 | F24: Wilson, David | G24: 5.2 | H24: =IF(((G24)<0),"+"&G24*(-1)&"",G24) -> 5.2 | I24: =D24+G24 -> 9.7 | J24: =IF((I24<0),"+"&I24*(-1)&"",I24) -> 9.7 | K24: =ABS(D24-G24) -> 0.7 | L24: 3 | M24: 6 | N24: =IF(ISTEXT(C24), Calcutta!F38, "") -> Kromis, Daniel
B25: 23 | C25: Sherman, Michael | D25: 7.5 | E25: =IF(((D25)<0),"+"&D25*(-1)&"",D25) -> 7.5 | F25: Elvers, Nate | G25: 2.8 | H25: =IF(((G25)<0),"+"&G25*(-1)&"",G25) -> 2.8 | I25: =D25+G25 -> 10.3 | J25: =IF((I25<0),"+"&I25*(-1)&"",I25) -> 10.3 | K25: =ABS(D25-G25) -> 4.7 | L25: 3 | M25: 7 | N25: =IF(ISTEXT(C25), Calcutta!F39, "") -> Brymer, Cory
B26: 24 | C26: Jones, Jason | D26: 4.9 | E26: =IF(((D26)<0),"+"&D26*(-1)&"",D26) -> 4.9 | F26: Qualls, Michael | G26: 5.4 | H26: =IF(((G26)<0),"+"&G26*(-1)&"",G26) -> 5.4 | I26: =D26+G26 -> 10.3 | J26: =IF((I26<0),"+"&I26*(-1)&"",I26) -> 10.3 | K26: =ABS(D26-G26) -> 0.5 | L26: 3 | M26: 8 | N26: =IF(ISTEXT(C26), Calcutta!F40, "") -> Fulmer, Austen
B27: 25 | C27: Brymer, Cory | D27: 4.4 | E27: =IF(((D27)<0),"+"&D27*(-1)&"",D27) -> 4.4 | F27: Manas, Shane | G27: 6 | H27: =IF(((G27)<0),"+"&G27*(-1)&"",G27) -> 6 | I27: =D27+G27 -> 10.4 | J27: =IF((I27<0),"+"&I27*(-1)&"",I27) -> 10.4 | K27: =ABS(D27-G27) -> 1.6 | L27: 4 | M27: 1 | N27: =IF(ISTEXT(C27), Calcutta!F44, "") -> Jones, Jason
B28: 26 | C28: Ledet, Jim | D28: 4.6 | E28: =IF(((D28)<0),"+"&D28*(-1)&"",D28) -> 4.6 | F28: Doucet, Jamie | G28: 5.8 | H28: =IF(((G28)<0),"+"&G28*(-1)&"",G28) -> 5.8 | I28: =D28+G28 -> 10.4 | J28: =IF((I28<0),"+"&I28*(-1)&"",I28) -> 10.4 | K28: =ABS(D28-G28) -> 1.2 | L28: 4 | M28: 2 | N28: =IF(ISTEXT(C28), Calcutta!F45, "") -> Aghazadeh, Abdol
B29: 27 | C29: Nugent, Tim | D29: 6.9 | E29: =IF(((D29)<0),"+"&D29*(-1)&"",D29) -> 6.9 | F29: Williams, Jeff | G29: 3.7 | H29: =IF(((G29)<0),"+"&G29*(-1)&"",G29) -> 3.7 | I29: =D29+G29 -> 10.6 | J29: =IF((I29<0),"+"&I29*(-1)&"",I29) -> 10.6 | K29: =ABS(D29-G29) -> 3.2 | L29: 4 | M29: 3 | N29: =IF(ISTEXT(C29), Calcutta!F46, "") -> Vaughn, Earl
B30: 28 | C30: Dietz, Jeffrey | D30: 5.2 | E30: =IF(((D30)<0),"+"&D30*(-1)&"",D30) -> 5.2 | F30: Morris, Brian | G30: 5.6 | H30: =IF(((G30)<0),"+"&G30*(-1)&"",G30) -> 5.6 | I30: =D30+G30 -> 10.8 | J30: =IF((I30<0),"+"&I30*(-1)&"",I30) -> 10.8 | K30: =ABS(D30-G30) -> 0.4 | L30: 4 | M30: 4 | N30: =IF(ISTEXT(C30), Calcutta!F47, "") -> Aghazadeh, Abdol
B31: 29 | C31: Tionloc, Alex | D31: 6 | E31: =IF(((D31)<0),"+"&D31*(-1)&"",D31) -> 6 | F31: Hicks, Clay | G31: 5 | H31: =IF(((G31)<0),"+"&G31*(-1)&"",G31) -> 5 | I31: =D31+G31 -> 11 | J31: =IF((I31<0),"+"&I31*(-1)&"",I31) -> 11 | K31: =ABS(D31-G31) -> 1 | L31: 4 | M31: 5 | N31: =IF(ISTEXT(C31), Calcutta!F48, "") -> Vidrine, Scot
B32: 30 | C32: Redding, Scott | D32: 5.8 | E32: =IF(((D32)<0),"+"&D32*(-1)&"",D32) -> 5.8 | F32: Redding, David | G32: 6 | H32: =IF(((G32)<0),"+"&G32*(-1)&"",G32) -> 6 | I32: =D32+G32 -> 11.8 | J32: =IF((I32<0),"+"&I32*(-1)&"",I32) -> 11.8 | K32: =ABS(D32-G32) -> 0.2 | L32: 4 | M32: 6 | N32: =IF(ISTEXT(C32), Calcutta!F49, "") -> Vaughn, Earl
B33: 31 | C33: Waclawsky, Paul | D33: 3.7 | E33: =IF(((D33)<0),"+"&D33*(-1)&"",D33) -> 3.7 | F33: Anderson, John | G33: 8.3 | H33: =IF(((G33)<0),"+"&G33*(-1)&"",G33) -> 8.3 | I33: =D33+G33 -> 12 | J33: =IF((I33<0),"+"&I33*(-1)&"",I33) -> 12 | K33: =ABS(D33-G33) -> 4.6 | L33: 4 | M33: 7 | N33: =IF(ISTEXT(C33), Calcutta!F50, "") -> Aghazadeh, Abdol
B34: 32 | C34: Erickson, Nick | D34: -0.1 | E34: =IF(((D34)<0),"+"&D34*(-1)&"",D34) -> +0.1 | F34: Erickson, Michael | G34: 12.4 | H34: =IF(((G34)<0),"+"&G34*(-1)&"",G34) -> 12.4 | I34: =D34+G34 -> 12.3 | J34: =IF((I34<0),"+"&I34*(-1)&"",I34) -> 12.3 | K34: =ABS(D34-G34) -> 12.5 | L34: 4 | M34: 8 | N34: =IF(ISTEXT(C34), Calcutta!F51, "") -> Cress, Pj
B35: 33 | C35: Scott, Paul | D35: 11 | E35: =IF(((D35)<0),"+"&D35*(-1)&"",D35) -> 11 | F35: Stopnik, Sean | G35: 1.5 | H35: =IF(((G35)<0),"+"&G35*(-1)&"",G35) -> 1.5 | I35: =D35+G35 -> 12.5 | J35: =IF((I35<0),"+"&I35*(-1)&"",I35) -> 12.5 | K35: =ABS(D35-G35) -> 9.5 | L35: 5 | M35: 1 | N35: =IF(ISTEXT(C35), Calcutta!F55, "") -> Schnautz, David
B36: 34 | C36: Marusco, Austin | D36: 9.1 | E36: =IF(((D36)<0),"+"&D36*(-1)&"",D36) -> 9.1 | F36: Joyce, Brendan | G36: 3.7 | H36: =IF(((G36)<0),"+"&G36*(-1)&"",G36) -> 3.7 | I36: =D36+G36 -> 12.8 | J36: =IF((I36<0),"+"&I36*(-1)&"",I36) -> 12.8 | K36: =ABS(D36-G36) -> 5.4 | L36: 5 | M36: 2 | N36: =IF(ISTEXT(C36), Calcutta!F56, "") -> Parent, Brian
B37: 35 | C37: Butler, Gregory | D37: 7.1 | E37: =IF(((D37)<0),"+"&D37*(-1)&"",D37) -> 7.1 | F37: Butler, Jonathan | G37: 5.8 | H37: =IF(((G37)<0),"+"&G37*(-1)&"",G37) -> 5.8 | I37: =D37+G37 -> 12.9 | J37: =IF((I37<0),"+"&I37*(-1)&"",I37) -> 12.9 | K37: =ABS(D37-G37) -> 1.3 | L37: 5 | M37: 3 | N37: =IF(ISTEXT(C37), Calcutta!F57, "") -> Capone, Michael
B38: 36 | C38: Drain, Zip | D38: 8 | E38: =IF(((D38)<0),"+"&D38*(-1)&"",D38) -> 8 | F38: Lange, Mark | G38: 5.2 | H38: =IF(((G38)<0),"+"&G38*(-1)&"",G38) -> 5.2 | I38: =D38+G38 -> 13.2 | J38: =IF((I38<0),"+"&I38*(-1)&"",I38) -> 13.2 | K38: =ABS(D38-G38) -> 2.8 | L38: 5 | M38: 4 | N38: =IF(ISTEXT(C38), Calcutta!F58, "") -> Butler, Gregory
B39: 37 | C39: Turner, Trevor | D39: 4 | E39: =IF(((D39)<0),"+"&D39*(-1)&"",D39) -> 4 | F39: Sherman, John | G39: 9.3 | H39: =IF(((G39)<0),"+"&G39*(-1)&"",G39) -> 9.3 | I39: =D39+G39 -> 13.3 | J39: =IF((I39<0),"+"&I39*(-1)&"",I39) -> 13.3 | K39: =ABS(D39-G39) -> 5.3 | L39: 5 | M39: 5 | N39: =IF(ISTEXT(C39), Calcutta!F59, "") -> Fulmer, Austen
B40: 38 | C40: Spisak, Brian | D40: 6.9 | E40: =IF(((D40)<0),"+"&D40*(-1)&"",D40) -> 6.9 | F40: Haarberg, Casey | G40: 6.6 | H40: =IF(((G40)<0),"+"&G40*(-1)&"",G40) -> 6.6 | I40: =D40+G40 -> 13.5 | J40: =IF((I40<0),"+"&I40*(-1)&"",I40) -> 13.5 | K40: =ABS(D40-G40) -> 0.3 | L40: 5 | M40: 6 | N40: =IF(ISTEXT(C40), Calcutta!F60, "") -> Spisak, Brian
B41: 39 | C41: Munoz, Juan | D41: 7.4 | E41: =IF(((D41)<0),"+"&D41*(-1)&"",D41) -> 7.4 | F41: Sanchez, Bert | G41: 6.3 | H41: =IF(((G41)<0),"+"&G41*(-1)&"",G41) -> 6.3 | I41: =D41+G41 -> 13.7 | J41: =IF((I41<0),"+"&I41*(-1)&"",I41) -> 13.7 | K41: =ABS(D41-G41) -> 1.1 | L41: 5 | M41: 7 | N41: =IF(ISTEXT(C41), Calcutta!F61, "") -> Aghazadeh, Abdol
...

Sheet Payout Calc
B2: Grand Totals | F2: Percentages | N2: Shootout | P2: =D4 -> 4023
B3: All Flights | D3: =D15+H15+L15+P15+T15+D48+H48+L48+P48+T48 -> 135100 | G3: =SUM(G4:G6) -> 1 | H3: Day Money | I3: =SUM(I4:I11) -> 1 | J3: Overall | K3: =SUM(K4:K7) -> 1 | N3: 1st | O3: 0.5 | P3: =FLOOR(($D$4*O3),5) -> 2010
B4: Shootout Bonus Pool | D4: =D16+H16+L16+P16+T16+D49+H49+L49+P49+T49 -> 4023 | F4: Shootout Bonus Pool | G4: 0.03 | H4: 1st | I4: 0.5 | J4: 1st | K4: 0.5 | N4: 2nd | O4: 0.3 | P4: =FLOOR(($D$4*O4),5) -> 1205
B5: Staff Gratuity | D5: =+D17+H17+L17+P17+T17+D50+H50+L50+P50+T50 -> 4023 | F5: Staff Gratuity | G5: 0.03 | H5: 2nd | I5: 0.3 | J5: 2nd | K5: 0.3 | N5: 3rd | O5: 0.2 | P5: =FLOOR(($D$4*O5),5) -> 800
B6: Total Avail Payout | D6: =D19+H19+L19+P19+T19+T52+P52+L52+H52+D52 -> 126054 | F6: Total Avail Payout | G6: 0.94 | H6: 3rd | I6: 0.2 | J6: 3rd | K6: 0.2 | N6: 4th | O6: 0 | P6: =FLOOR(($D$4*O6),5) -> 0
B7: Security / Auctioneer (fixed) | D7: 1000 | F7: Flight Wnrs % of TAP | G7: 0.65 | H7: 4th | I7: 0 | J7: 4th | K7: 0 | O7: Sum | P7: =SUM(P3:P6) -> 4015
F8: Day Money % of TAP | G8: 0.35 | H8: 5th | I8: 0 | N8: Total Leftover Shootout | P8: =P2-P7 -> 8
B9: Leftover Funds | D9: =D44+H44+L44+P44+T44+T77+P77+L77+H77+D77+P8 -> 159.4 | H9: 6th | I9: 0
H10: 7th | I10: 0
H11: 8th | I11: 0
B15: Flight #1 | C15: Total | D15: =Calcutta!I11 -> 20600 | F15: Flight #2 | G15: Total | H15: =Calcutta!I22 -> 21000 | J15: Flight #3 | K15: Total | L15: =Calcutta!I33 -> 13400 | N15: Flight #4 | O15: Total | P15: =Calcutta!I44 -> 19500 | R15: Flight #5 | S15: Total | T15: =Calcutta!I55 -> 12000
B16: ="Bonus Pool (" & (TEXT($G$4, "0%")) & ")" -> Bonus Pool (3%) | D16: =(D15-D18)*$G$4 -> 615 | F16: ="Bonus Pool (" & (TEXT($G$4, "0%")) & ")" -> Bonus Pool (3%) | H16: =(H15-H18)*$G$4 -> 627 | J16: ="Bonus Pool (" & (TEXT($G$4, "0%")) & ")" -> Bonus Pool (3%) | L16: =(L15-L18)*$G$4 -> 399 | N16: ="Bonus Pool (" & (TEXT($G$4, "0%")) & ")" -> Bonus Pool (3%) | P16: =(P15-P18)*$G$4 -> 582 | R16: ="Bonus Pool (" & (TEXT($G$4, "0%")) & ")" -> Bonus Pool (3%) | T16: =(T15-T18)*$G$4 -> 357
B17: ="Staff Gratuity (" & (TEXT($G$5, "0%")) & ")" -> Staff Gratuity (3%) | D17: =(D15-D18)*$G$5 -> 615 | F17: ="Staff Gratuity (" & (TEXT($G$5, "0%")) & ")" -> Staff Gratuity (3%) | H17: =(H15-H18)*$G$5 -> 627 | J17: ="Staff Gratuity (" & (TEXT($G$5, "0%")) & ")" -> Staff Gratuity (3%) | L17: =(L15-L18)*$G$5 -> 399 | N17: ="Staff Gratuity (" & (TEXT($G$5, "0%")) & ")" -> Staff Gratuity (3%) | P17: =(P15-P18)*$G$5 -> 582 | R17: ="Staff Gratuity (" & (TEXT($G$5, "0%")) & ")" -> Staff Gratuity (3%) | T17: =(T15-T18)*$G$5 -> 357
B18: Security Cost (fixed) | D18: =$D$7/10 -> 100 | F18: Security Cost (fixed) | H18: =$D$7/10 -> 100 | J18: Security Cost (fixed) | L18: =$D$7/10 -> 100 | N18: Security Cost (fixed) | P18: =$D$7/10 -> 100 | R18: Security Cost (fixed) | T18: =$D$7/10 -> 100
B19: ="Total Available Payout (" & (TEXT($G$6, "0%")) & ")" -> Total Available Payout (94%) | D19: =((D15-D18)*$G$6) -> 19270 | F19: ="Total Available Payout (" & (TEXT($G$6, "0%")) & ")" -> Total Available Payout (94%) | H19: =(H15-H18)*$G$6 -> 19646 | J19: ="Total Available Payout (" & (TEXT($G$6, "0%")) & ")" -> Total Available Payout (94%) | L19: =(L15-L18)*$G$6 -> 12502 | N19: ="Total Available Payout (" & (TEXT($G$6, "0%")) & ")" -> Total Available Payout (94%) | P19: =(P15-P18)*$G$6 -> 18236 | R19: ="Total Available Payout (" & (TEXT($G$6, "0%")) & ")" -> Total Available Payout (94%) | T19: =(T15-T18)*$G$6 -> 11186
C20: Sum | D20: =SUM(D16:E19) -> 20600 | G20: Sum | H20: =SUM(H16:I19) -> 21000 | K20: Sum | L20: =SUM(L16:M19) -> 13400 | O20: Sum | P20: =SUM(P16:Q19) -> 19500 | S20: Sum | T20: =SUM(T16:U19) -> 12000
B22: Flight Winners | F22: Flight Winners | J22: Flight Winners | N22: Flight Winners | R22: Flight Winners
B23: =(TEXT($G$7, "0%")) & " of Total Available Payout" -> 65% of Total Available Payout | D23: =D19*$G$7 -> 12525.5 | F23: =(TEXT($G$7, "0%")) & " of Total Available Payout" -> 65% of Total Available Payout | H23: =H19*$G$7 -> 12769.9 | J23: =(TEXT($G$7, "0%")) & " of Total Available Payout" -> 65% of Total Available Payout | L23: =L19*$G$7 -> 8126.3 | N23: =(TEXT($G$7, "0%")) & " of Total Available Payout" -> 65% of Total Available Payout | P23: =P19*$G$7 -> 11853.4 | R23: =(TEXT($G$7, "0%")) & " of Total Available Payout" -> 65% of Total Available Payout | T23: =T19*$G$7 -> 7270.9
B24: 1st | C24: =$K$4 -> 0.5 | D24: =FLOOR((D23*$K$4),5) -> 6260 | F24: 1st | G24: =$K$4 -> 0.5 | H24: =FLOOR((H23*$K$4),5) -> 6380 | J24: 1st | K24: =$K$4 -> 0.5 | L24: =FLOOR((L23*$K$4),5) -> 4060 | N24: 1st | O24: =$K$4 -> 0.5 | P24: =FLOOR((P23*$K$4),5) -> 5925 | R24: 1st | S24: =$K$4 -> 0.5 | T24: =FLOOR((T23*$K$4),5) -> 3635
B25: 2nd | C25: =$K$5 -> 0.3 | D25: =FLOOR((D23*$K$5),5) -> 3755 | F25: 2nd | G25: =$K$5 -> 0.3 | H25: =FLOOR((H23*$K$5),5) -> 3830 | J25: 2nd | K25: =$K$5 -> 0.3 | L25: =FLOOR((L23*$K$5),5) -> 2435 | N25: 2nd | O25: =$K$5 -> 0.3 | P25: =FLOOR((P23*$K$5),5) -> 3555 | R25: 2nd | S25: =$K$5 -> 0.3 | T25: =FLOOR((T23*$K$5),5) -> 2180
B26: 3rd | C26: =$K$6 -> 0.2 | D26: =FLOOR((D23*$K$6),5) -> 2505 | F26: 3rd | G26: =$K$6 -> 0.2 | H26: =FLOOR((H23*$K$6),5) -> 2550 | J26: 3rd | K26: =$K$6 -> 0.2 | L26: =FLOOR((L23*$K$6),5) -> 1625 | N26: 3rd | O26: =$K$6 -> 0.2 | P26: =FLOOR((P23*$K$6),5) -> 2370 | R26: 3rd | S26: =$K$6 -> 0.2 | T26: =FLOOR((T23*$K$6),5) -> 1450
B27: 4th | C27: =$K$7 -> 0 | D27: =FLOOR((D23*$K$7),5) -> 0 | F27: 4th | G27: =$K$7 -> 0 | H27: =FLOOR((H23*$K$7),5) -> 0 | J27: 4th | K27: =$K$7 -> 0 | L27: =FLOOR((L23*$K$7),5) -> 0 | N27: 4th | O27: =$K$7 -> 0 | P27: =FLOOR((P23*$K$7),5) -> 0 | R27: 4th | S27: =$K$7 -> 0 | T27: =FLOOR((T23*$K$7),5) -> 0
B28: Sum | C28: =SUM(C24:C27) -> 1 | D28: =SUM(D24:D27) -> 12520 | F28: Sum | G28: =SUM(G24:G27) -> 1 | H28: =SUM(H24:H27) -> 12760 | J28: Sum | K28: =SUM(K24:K27) -> 1 | L28: =SUM(L24:L27) -> 8120 | N28: Sum | O28: =SUM(O24:O27) -> 1 | P28: =SUM(P24:P27) -> 11850 | R28: Sum | S28: =SUM(S24:S27) -> 1 | T28: =SUM(T24:T27) -> 7265
B29: Leftover | D29: =D23-D28 -> 5.5 | F29: Leftover | H29: =H23-H28 -> 9.9 | J29: Leftover | L29: =L23-L28 -> 6.3 | N29: Leftover | P29: =P23-P28 -> 3.4 | R29: Leftover | T29: =T23-T28 -> 5.9
B31: Day Money | F31: Day Money | J31: Day Money | N31: Day Money | R31: Day Money
B32: =(TEXT($G$8, "0%")) & " of Total Available Payout" -> 35% of Total Available Payout | D32: =D19*$G$8 -> 6744.5 | F32: =(TEXT($G$8, "0%")) & " of Total Available Payout" -> 35% of Total Available Payout | H32: =H19*$G$8 -> 6876.1 | J32: =(TEXT($G$8, "0%")) & " of Total Available Payout" -> 35% of Total Available Payout | L32: =L19*$G$8 -> 4375.7 | N32: =(TEXT($G$8, "0%")) & " of Total Available Payout" -> 35% of Total Available Payout | P32: =P19*$G$8 -> 6382.6 | R32: =(TEXT($G$8, "0%")) & " of Total Available Payout" -> 35% of Total Available Payout | T32: =T19*$G$8 -> 3915.1
B33: Daily Payout (3 days) | D33: =D32/3 -> 2248.1667 | F33: Daily Payout (3 days) | H33: =H32/3 -> 2292.0333 | J33: Daily Payout (3 days) | L33: =L32/3 -> 1458.5667 | N33: Daily Payout (3 days) | P33: =P32/3 -> 2127.5333 | R33: Daily Payout (3 days) | T33: =T32/3 -> 1305.0333
B34: 1st | C34: =$I$4 -> 0.5 | D34: =FLOOR((C34*$D$33),5) -> 1120 | F34: 1st | G34: =$I$4 -> 0.5 | H34: =FLOOR((G34*$H$33),5) -> 1145 | J34: 1st | K34: =$I$4 -> 0.5 | L34: =FLOOR((K34*$L$33),5) -> 725 | N34: 1st | O34: =$I$4 -> 0.5 | P34: =FLOOR((O34*$P$33),5) -> 1060 | R34: 1st | S34: =$I$4 -> 0.5 | T34: =FLOOR((S34*$T$33),5) -> 650
B35: 2nd | C35: =$I$5 -> 0.3 | D35: =FLOOR((C35*$D$33),5) -> 670 | F35: 2nd | G35: =$I$5 -> 0.3 | H35: =FLOOR((G35*$H$33),5) -> 685 | J35: 2nd | K35: =$I$5 -> 0.3 | L35: =FLOOR((K35*$L$33),5) -> 435 | N35: 2nd | O35: =$I$5 -> 0.3 | P35: =FLOOR((O35*$P$33),5) -> 635 | R35: 2nd | S35: =$I$5 -> 0.3 | T35: =FLOOR((S35*$T$33),5) -> 390
B36: 3rd | C36: =$I$6 -> 0.2 | D36: =FLOOR((C36*$D$33),5) -> 445 | F36: 3rd | G36: =$I$6 -> 0.2 | H36: =FLOOR((G36*$H$33),5) -> 455 | J36: 3rd | K36: =$I$6 -> 0.2 | L36: =FLOOR((K36*$L$33),5) -> 290 | N36: 3rd | O36: =$I$6 -> 0.2 | P36: =FLOOR((O36*$P$33),5) -> 425 | R36: 3rd | S36: =$I$6 -> 0.2 | T36: =FLOOR((S36*$T$33),5) -> 260
B37: 4th | C37: =$I$7 -> 0 | D37: =FLOOR((C37*$D$33),5) -> 0 | F37: 4th | G37: =$I$7 -> 0 | H37: =FLOOR((G37*$H$33),5) -> 0 | J37: 4th | K37: =$I$7 -> 0 | L37: =FLOOR((K37*$L$33),5) -> 0 | N37: 4th | O37: =$I$7 -> 0 | P37: =FLOOR((O37*$P$33),5) -> 0 | R37: 4th | S37: =$I$7 -> 0 | T37: =FLOOR((S37*$T$33),5) -> 0
B38: 5th | C38: =$I$8 -> 0 | D38: =FLOOR((C38*$D$33),5) -> 0 | F38: 5th | G38: =$I$8 -> 0 | H38: =FLOOR((G38*$H$33),5) -> 0 | J38: 5th | K38: =$I$8 -> 0 | L38: =FLOOR((K38*$L$33),5) -> 0 | N38: 5th | O38: =$I$8 -> 0 | P38: =FLOOR((O38*$P$33),5) -> 0 | R38: 5th | S38: =$I$8 -> 0 | T38: =FLOOR((S38*$T$33),5) -> 0
B39: 6th | C39: =$I$9 -> 0 | D39: =FLOOR((C39*$D$33),5) -> 0 | F39: 6th | G39: =$I$9 -> 0 | H39: =FLOOR((G39*$H$33),5) -> 0 | J39: 6th | K39: =$I$9 -> 0 | L39: =FLOOR((K39*$L$33),5) -> 0 | N39: 6th | O39: =$I$9 -> 0 | P39: =FLOOR((O39*$P$33),5) -> 0 | R39: 6th | S39: =$I$9 -> 0 | T39: =FLOOR((S39*$T$33),5) -> 0
B40: 7th | C40: =$I$10 -> 0 | D40: =FLOOR((C40*$D$33),5) -> 0 | F40: 7th | G40: =$I$10 -> 0 | H40: =FLOOR((G40*$H$33),5) -> 0 | J40: 7th | K40: =$I$10 -> 0 | L40: =FLOOR((K40*$L$33),5) -> 0 | N40: 7th | O40: =$I$10 -> 0 | P40: =FLOOR((O40*$P$33),5) -> 0 | R40: 7th | S40: =$I$10 -> 0 | T40: =FLOOR((S40*$T$33),5) -> 0
B41: 8th | C41: =$I$11 -> 0 | D41: =FLOOR((C41*$D$33),5) -> 0 | F41: 8th | G41: =$I$11 -> 0 | H41: =FLOOR((G41*$D$33),5) -> 0 | J41: 8th | K41: =$I$11 -> 0 | L41: =FLOOR((K41*$L$33),5) -> 0 | N41: 8th | O41: =$I$11 -> 0 | P41: =FLOOR((O41*$P$33),5) -> 0 | R41: 8th | S41: =$I$11 -> 0 | T41: =FLOOR((S41*$T$33),5) -> 0
B42: Sum | C42: =SUM(C34:C41) -> 1 | D42: =SUM(D34:D41) -> 2235 | F42: Sum | G42: =SUM(G34:G41) -> 1 | H42: =SUM(H34:H41) -> 2285 | J42: Sum | K42: =SUM(K34:K41) -> 1 | L42: =SUM(L34:L41) -> 1450 | N42: Sum | O42: =SUM(O34:O41) -> 1 | P42: =SUM(P34:P41) -> 2120 | R42: Sum | S42: =SUM(S34:S41) -> 1 | T42: =SUM(T34:T41) -> 1300
B43: Leftover | D43: =D33-D42 -> 13.166667 | F43: Leftover | H43: =H33-H42 -> 7.0333333 | J43: Leftover | L43: =L33-L42 -> 8.5666667 | N43: Leftover | P43: =P33-P42 -> 7.5333333 | R43: Leftover | T43: =T33-T42 -> 5.0333333
B44: Total Leftover Flight #1 | D44: =D29+D43 -> 18.666667 | F44: Total Leftover Flight #2 | H44: =H29+H43 -> 16.933333 | J44: Total Leftover Flight #3 | L44: =L29+L43 -> 14.866667 | N44: Total Leftover Flight #4 | P44: =P29+P43 -> 10.933333 | R44: Total Leftover Flight #5 | T44: =T29+T43 -> 10.933333
B48: Flight #6 | C48: Total | D48: =Calcutta!I66 -> 11400 | F48: Flight #7 | G48: Total | H48: =Calcutta!I77 -> 10300 | J48: Flight #8 | K48: Total | L48: =Calcutta!I88 -> 9300 | N48: Flight #9 | O48: Total | P48: =Calcutta!I99 -> 9300 | R48: Flight #10 | S48: Total | T48: =Calcutta!I110 -> 8300
B49: ="Bonus Pool (" & (TEXT($G$4, "0%")) & ")" -> Bonus Pool (3%) | D49: =(D48-D51)*$G$4 -> 339 | F49: ="Bonus Pool (" & (TEXT($G$4, "0%")) & ")" -> Bonus Pool (3%) | H49: =(H48-H51)*$G$4 -> 306 | J49: ="Bonus Pool (" & (TEXT($G$4, "0%")) & ")" -> Bonus Pool (3%) | L49: =(L48-L51)*$G$4 -> 276 | N49: ="Bonus Pool (" & (TEXT($G$4, "0%")) & ")" -> Bonus Pool (3%) | P49: =(P48-P51)*$G$4 -> 276 | R49: ="Bonus Pool (" & (TEXT($G$4, "0%")) & ")" -> Bonus Pool (3%) | T49: =(T48-T51)*$G$4 -> 246
...

Sheet Quota Calc v1
A3: Flight #1 | E3: Day 1 | G3: Day 2 | I3: Day 3
A4: Flight | B4: Team # | C4: Member | D4: Guest | E4: Quota | F4: Results | G4: Quota | H4: Results | I4: Quota | J4: Results
A5: 1 | B5: 1 | C5: =IF('Master Player List'!L3=1,'Master Player List'!C3,"") -> Brijalba, Rufus | D5: =IF('Master Player List'!L3=1,'Master Player List'!F3,"") -> Peck, Colin | E5: =IF('Master Player List'!L3=1,'Master Player List'!I3,"") -> -5.2
A6: 1 | B6: 2 | C6: =IF('Master Player List'!L4=1,'Master Player List'!C4,"") -> Paschke, Michael | D6: =IF('Master Player List'!L4=1,'Master Player List'!F4,"") -> Montes, Daniel | E6: =IF('Master Player List'!L4=1,'Master Player List'!I4,"") -> -0.7 | M6: Creat Master Formula Page?
A7: 1 | B7: 3 | C7: =IF('Master Player List'!L5=1,'Master Player List'!C5,"") -> Harwood, Michael | D7: =IF('Master Player List'!L5=1,'Master Player List'!F5,"") -> Diaz, Gerry | E7: =IF('Master Player List'!L5=1,'Master Player List'!I5,"") -> 0.1 | M7: Flight Daily Placing Calcs?
A8: 1 | B8: 4 | C8: =IF('Master Player List'!L6=1,'Master Player List'!C6,"") -> Lambert, Jeff | D8: =IF('Master Player List'!L6=1,'Master Player List'!F6,"") -> White, Jason | E8: =IF('Master Player List'!L6=1,'Master Player List'!I6,"") -> 1.8 | M8: Tie breaker Calcs?
A9: 1 | B9: 5 | C9: =IF('Master Player List'!L7=1,'Master Player List'!C7,"") -> Kim, Steven | D9: =IF('Master Player List'!L7=1,'Master Player List'!F7,"") -> Kerrigan, Mike | E9: =IF('Master Player List'!L7=1,'Master Player List'!I7,"") -> 2.9
A10: 1 | B10: 6 | C10: =IF('Master Player List'!L8=1,'Master Player List'!C8,"") -> Maples, Brent | D10: =IF('Master Player List'!L8=1,'Master Player List'!F8,"") -> Buratto, Mark | E10: =IF('Master Player List'!L8=1,'Master Player List'!I8,"") -> 3.8
A11: 1 | B11: 7 | C11: =IF('Master Player List'!L9=1,'Master Player List'!C9,"") -> Darter, Bret | D11: =IF('Master Player List'!L9=1,'Master Player List'!F9,"") -> Caldwell, Trey | E11: =IF('Master Player List'!L9=1,'Master Player List'!I9,"") -> 4.1
A12: 1 | B12: 8 | C12: =IF('Master Player List'!L10=1,'Master Player List'!C10,"") -> Black, Gene | D12: =IF('Master Player List'!L10=1,'Master Player List'!F10,"") -> Tilson, Scott | E12: =IF('Master Player List'!L10=1,'Master Player List'!I10,"") -> 4.5
A13: 1 | B13: 9 | C13: =IF('Master Player List'!L11=1,'Master Player List'!C11,"") | D13: =IF('Master Player List'!L11=1,'Master Player List'!F11,"") | E13: =IF('Master Player List'!L11=1,'Master Player List'!I11,"")
A14: 1 | B14: 10 | C14: =IF('Master Player List'!L12=1,'Master Player List'!C12,"") | D14: =IF('Master Player List'!L12=1,'Master Player List'!F12,"") | E14: =IF('Master Player List'!L12=1,'Master Player List'!I12,"")
A15: 1 | B15: 11 | C15: =IF('Master Player List'!L13=1,'Master Player List'!C13,"") | D15: =IF('Master Player List'!L13=1,'Master Player List'!F13,"") | E15: =IF('Master Player List'!L13=1,'Master Player List'!I13,"")
A16: 1 | B16: 12 | C16: =IF('Master Player List'!L14=1,'Master Player List'!C14,"") | D16: =IF('Master Player List'!L14=1,'Master Player List'!F14,"") | E16: =IF('Master Player List'!L14=1,'Master Player List'!I14,"")
A17: 1 | B17: 13 | C17: =IF('Master Player List'!L15=1,'Master Player List'!C15,"") | D17: =IF('Master Player List'!L15=1,'Master Player List'!F15,"") | E17: =IF('Master Player List'!L15=1,'Master Player List'!I15,"")
A18: 1 | B18: 14 | C18: =IF('Master Player List'!L16=1,'Master Player List'!C16,"") | D18: =IF('Master Player List'!L16=1,'Master Player List'!F16,"") | E18: =IF('Master Player List'!L16=1,'Master Player List'!I16,"")
A19: 1 | B19: 15 | C19: =IF('Master Player List'!L17=1,'Master Player List'!C17,"") | D19: =IF('Master Player List'!L17=1,'Master Player List'!F17,"") | E19: =IF('Master Player List'!L17=1,'Master Player List'!I17,"")
A20: 1 | B20: 16 | C20: =IF('Master Player List'!L18=1,'Master Player List'!C18,"") | D20: =IF('Master Player List'!L18=1,'Master Player List'!F18,"") | E20: =IF('Master Player List'!L18=1,'Master Player List'!I18,"")
... A26: 1 | B26: 22 | C26: =IF('Master Player List'!L24=1,'Master Player List'!C24,"") | D26: =IF('Master Player List'!L24=1,'Master Player List'!F24,"") | E26: =IF('Master Player List'!L24=1,'Master Player List'!I24,"")
C27: =IF('Master Player List'!L25=1,'Master Player List'!C25,"") | D27: =IF('Master Player List'!L25=1,'Master Player List'!F25,"")
C28: =IF('Master Player List'!L2=1,'Master Player List'!C2,"") | D28: =IF('Master Player List'!L2=1,'Master Player List'!F2,"")
A29: Flight #2 | E29: Day 1 | G29: Day 2 | I29: Day 3
A30: Flight | B30: Team # | C30: Member | D30: Guest | E30: Quota | F30: Results | G30: Quota | H30: Results | I30: Quota | J30: Results
A31: 2 | B31: 1 | C31: =IF('Master Player List'!L25=2,'Master Player List'!C25,"") | D31: =IF('Master Player List'!L25=2,'Master Player List'!F25,"") | E31: =IF('Master Player List'!L25=2,'Master Player List'!I25,"")
A32: 2 | B32: 2 | C32: =IF('Master Player List'!L26=2,'Master Player List'!C26,"") | D32: =IF('Master Player List'!L26=2,'Master Player List'!F26,"") | E32: =IF('Master Player List'!L26=2,'Master Player List'!I26,"")
A33: 2 | B33: 3 | C33: =IF('Master Player List'!L27=2,'Master Player List'!C27,"") | D33: =IF('Master Player List'!L27=2,'Master Player List'!F27,"") | E33: =IF('Master Player List'!L27=2,'Master Player List'!I27,"")
A34: 2 | B34: 4 | C34: =IF('Master Player List'!L28=2,'Master Player List'!C28,"") | D34: =IF('Master Player List'!L28=2,'Master Player List'!F28,"") | E34: =IF('Master Player List'!L28=2,'Master Player List'!I28,"")
A35: 2 | B35: 5 | C35: =IF('Master Player List'!L29=2,'Master Player List'!C29,"") | D35: =IF('Master Player List'!L29=2,'Master Player List'!F29,"") | E35: =IF('Master Player List'!L29=2,'Master Player List'!I29,"")
A36: 2 | B36: 6 | C36: =IF('Master Player List'!L30=2,'Master Player List'!C30,"") | D36: =IF('Master Player List'!L30=2,'Master Player List'!F30,"") | E36: =IF('Master Player List'!L30=2,'Master Player List'!I30,"")
A37: 2 | B37: 7 | C37: =IF('Master Player List'!L31=2,'Master Player List'!C31,"") | D37: =IF('Master Player List'!L31=2,'Master Player List'!F31,"") | E37: =IF('Master Player List'!L31=2,'Master Player List'!I31,"")
A38: 2 | B38: 8 | C38: =IF('Master Player List'!L32=2,'Master Player List'!C32,"") | D38: =IF('Master Player List'!L32=2,'Master Player List'!F32,"") | E38: =IF('Master Player List'!L32=2,'Master Player List'!I32,"")
A39: 2 | B39: 9 | C39: =IF('Master Player List'!L33=2,'Master Player List'!C33,"") | D39: =IF('Master Player List'!L33=2,'Master Player List'!F33,"") | E39: =IF('Master Player List'!L33=2,'Master Player List'!I33,"")
A40: 2 | B40: 10 | C40: =IF('Master Player List'!L34=2,'Master Player List'!C34,"") | D40: =IF('Master Player List'!L34=2,'Master Player List'!F34,"") | E40: =IF('Master Player List'!L34=2,'Master Player List'!I34,"")
A41: 2 | B41: 11 | C41: =IF('Master Player List'!L35=2,'Master Player List'!C35,"") | D41: =IF('Master Player List'!L35=2,'Master Player List'!F35,"") | E41: =IF('Master Player List'!L35=2,'Master Player List'!I35,"")
A42: 2 | B42: 12 | C42: =IF('Master Player List'!L36=2,'Master Player List'!C36,"") | D42: =IF('Master Player List'!L36=2,'Master Player List'!F36,"") | E42: =IF('Master Player List'!L36=2,'Master Player List'!I36,"")
... A52: 2 | B52: 22 | C52: =IF('Master Player List'!L46=2,'Master Player List'!C46,"") | D52: =IF('Master Player List'!L46=2,'Master Player List'!F46,"") | E52: =IF('Master Player List'!L46=2,'Master Player List'!I46,"")
A55: Flight #3 | E55: Day 1 | G55: Day 2 | I55: Day 3
A56: Flight | B56: Team # | C56: Member | D56: Guest | E56: Quota | F56: Results | G56: Quota | H56: Results | I56: Quota | J56: Results
A57: 3 | B57: 1 | C57: =IF('Master Player List'!L47=3,'Master Player List'!C47,"") | D57: =IF('Master Player List'!L47=3,'Master Player List'!F47,"") | E57: =IF('Master Player List'!L47=3,'Master Player List'!I47,"")
A58: 3 | B58: 2 | C58: =IF('Master Player List'!L48=3,'Master Player List'!C48,"") | D58: =IF('Master Player List'!L48=3,'Master Player List'!F48,"") | E58: =IF('Master Player List'!L48=3,'Master Player List'!I48,"")
...

Sheet Formatting
B1: Member | C1: Handicap | D1: Guest | E1: Handicap | F1: Row
D2: Brijalba, Rufus | E2: -3.1 | F2: =MOD(ROW(),2) -> 0
B3: Brijalba, Rufus | C3: -3.1 | D3: Peck, Colin | E3: -2.1 | F3: =MOD(ROW(),2) -> 1
B4: Peck, Colin | C4: -2.1 | D4: Paschke, Michael | E4: 3.6 | F4: =MOD(ROW(),2) -> 0
B5: Paschke, Michael | C5: 3.6 | D5: Montes, Daniel | E5: -4.3 | F5: =MOD(ROW(),2) -> 1
B6: Montes, Daniel | C6: -4.3 | D6: Harwood, Michael | E6: -0.5 | F6: =MOD(ROW(),2) -> 0
B7: Harwood, Michael | C7: -0.5 | D7: Diaz, Gerry | E7: 0.6 | F7: =MOD(ROW(),2) -> 1
B8: Diaz, Gerry | C8: 0.6 | D8: Lambert, Jeff | E8: 0.5 | F8: =MOD(ROW(),2) -> 0
B9: Lambert, Jeff | C9: 0.5 | D9: White, Jason | E9: 1.3 | F9: =MOD(ROW(),2) -> 1
B10: White, Jason | C10: 1.3 | D10: Kim, Steven | E10: 2.8 | F10: =MOD(ROW(),2) -> 0
B11: Kim, Steven | C11: 2.8 | D11: Kerrigan, Mike | E11: 0.1 | F11: =MOD(ROW(),2) -> 1
B12: Kerrigan, Mike | C12: 0.1 | D12: Maples, Brent | E12: -0.7 | F12: =MOD(ROW(),2) -> 0
B13: Maples, Brent | C13: -0.7 | D13: Buratto, Mark | E13: 4.5 | F13: =MOD(ROW(),2) -> 1
B14: Buratto, Mark | C14: 4.5 | D14: Darter, Bret | E14: 0.2 | F14: =MOD(ROW(),2) -> 0
... B161: Parent, Brian | C161: 21.6 | D161: Holmes, Justin | E161: 19.7 | F161: =MOD(ROW(),2) -> 1
B162: Holmes, Justin | C162: 19.7 | F162: =MOD(ROW(),2) -> 0

Sheet Sheet1
A2: Flight | B2: Team | C2: Member | D2: Guest | E2: Owner | F2: Bid | G2: TeamHCP | H2: MemberHCP | I2: GuestHCP | L2: Flight | M2: Place | N2: Amount | O2: Winner | P2: Owner | S2: Flight | T2: Day | U2: Place | V2: Amount | W2: Winner | X2: Owner
A3: ='Master Player List'!L3 -> 1 | B3: ='Master Player List'!M3 -> 1 | C3: ='Master Player List'!C3 -> Brijalba, Rufus | D3: ='Master Player List'!F3 -> Peck, Colin | E3: ='Master Player List'!N3 -> Brijalba, Rufus | F3: =Calcutta!E11 -> 3200 | G3: ='Master Player List'!J3 -> +5.2 | H3: ='Master Player List'!E3 -> +3.1 | I3: ='Master Player List'!H3 -> +2.1 | L3: 1 | M3: 1 | N3: =Calcutta!I14 -> 6260 | O3: =Calcutta!J14 -> Lambert, Jeff | P3: =Calcutta!K14 -> Aghazadeh, Abdol | S3: 1 | T3: Thursday | U3: 1 | V3: =Calcutta!$N$14 -> 1120 | W3: =Calcutta!O14 -> Brijalba, Rufus | X3: =Calcutta!P14 -> Brijalba, Rufus
A4: ='Master Player List'!L4 -> 1 | B4: ='Master Player List'!M4 -> 2 | C4: ='Master Player List'!C4 -> Paschke, Michael | D4: ='Master Player List'!F4 -> Montes, Daniel | E4: ='Master Player List'!N4 -> Edwards, Patric | F4: =Calcutta!E12 -> 4000 | G4: ='Master Player List'!J4 -> +0.7 | H4: ='Master Player List'!E4 -> 3.6 | I4: ='Master Player List'!H4 -> +4.3 | L4: 1 | M4: 2 | N4: =Calcutta!I15 -> 3755 | O4: =Calcutta!J15 -> Harwood, Michael | P4: =Calcutta!K15 -> Harwood, Michael | S4: 1 | T4: Thursday | U4: 2 | V4: =Calcutta!$N$15 -> 670 | W4: =Calcutta!O15 -> Kim, Steven | X4: =Calcutta!P15 -> Godhania, Vikas
A5: ='Master Player List'!L5 -> 1 | B5: ='Master Player List'!M5 -> 3 | C5: ='Master Player List'!C5 -> Harwood, Michael | D5: ='Master Player List'!F5 -> Diaz, Gerry | E5: ='Master Player List'!N5 -> Harwood, Michael | F5: =Calcutta!E13 -> 2200 | G5: ='Master Player List'!J5 -> 0.1 | H5: ='Master Player List'!E5 -> +0.5 | I5: ='Master Player List'!H5 -> 0.6 | L5: 1 | M5: 3 | N5: =Calcutta!I16 -> 2505 | O5: =Calcutta!J16 -> Paschke, Michael | P5: =Calcutta!K16 -> Edwards, Patric | S5: 1 | T5: Thursday | U5: 3 | V5: =Calcutta!$N$16 -> 445 | W5: =Calcutta!O16 -> Paschke, Michael | X5: =Calcutta!P16 -> Edwards, Patric
A6: ='Master Player List'!L6 -> 1 | B6: ='Master Player List'!M6 -> 4 | C6: ='Master Player List'!C6 -> Lambert, Jeff | D6: ='Master Player List'!F6 -> White, Jason | E6: ='Master Player List'!N6 -> Aghazadeh, Abdol | F6: =Calcutta!E14 -> 1900 | G6: ='Master Player List'!J6 -> 1.8 | H6: ='Master Player List'!E6 -> 0.5 | I6: ='Master Player List'!H6 -> 1.3 | L6: 2 | M6: 1 | N6: =Calcutta!I25 -> 6380 | O6: =Calcutta!J25 -> Sherman, Michael | P6: =Calcutta!K25 -> Brymer, Cory | S6: 1 | T6: Friday | U6: 1 | V6: =Calcutta!$N$14 -> 1120 | W6: =Calcutta!Q14 -> Paschke, Michael | X6: =Calcutta!R14 -> Edwards, Patric
A7: ='Master Player List'!L7 -> 1 | B7: ='Master Player List'!M7 -> 5 | C7: ='Master Player List'!C7 -> Kim, Steven | D7: ='Master Player List'!F7 -> Kerrigan, Mike | E7: ='Master Player List'!N7 -> Godhania, Vikas | F7: =Calcutta!E15 -> 1600 | G7: ='Master Player List'!J7 -> 2.9 | H7: ='Master Player List'!E7 -> 2.8 | I7: ='Master Player List'!H7 -> 0.1 | L7: 2 | M7: 2 | N7: =Calcutta!I26 -> 3830 | O7: =Calcutta!J26 -> Fulmer, Austen | P7: =Calcutta!K26 -> Aghazadeh, Abdol | S7: 1 | T7: Friday | U7: 2 | V7: =Calcutta!$N$15 -> 670 | W7: =Calcutta!Q15 -> Paschke, Michael | X7: =Calcutta!R15 -> Edwards, Patric
A8: ='Master Player List'!L8 -> 1 | B8: ='Master Player List'!M8 -> 6 | C8: ='Master Player List'!C8 -> Maples, Brent | D8: ='Master Player List'!F8 -> Buratto, Mark | E8: ='Master Player List'!N8 -> Maples, Brent | F8: =Calcutta!E16 -> 2500 | G8: ='Master Player List'!J8 -> 3.8 | H8: ='Master Player List'!E8 -> +0.7 | I8: ='Master Player List'!H8 -> 4.5 | L8: 2 | M8: 3 | N8: =Calcutta!I27 -> 2550 | O8: =Calcutta!J27 -> Lau, Jason | P8: =Calcutta!K27 -> Brymer, Cory | S8: 1 | T8: Friday | U8: 3 | V8: =Calcutta!$N$16 -> 445 | W8: =Calcutta!Q16 -> Paschke, Michael | X8: =Calcutta!R16 -> Edwards, Patric
A9: ='Master Player List'!L9 -> 1 | B9: ='Master Player List'!M9 -> 7 | C9: ='Master Player List'!C9 -> Darter, Bret | D9: ='Master Player List'!F9 -> Caldwell, Trey | E9: ='Master Player List'!N9 -> Darter, Bret | F9: =Calcutta!E17 -> 2200 | G9: ='Master Player List'!J9 -> 4.1 | H9: ='Master Player List'!E9 -> 0.2 | I9: ='Master Player List'!H9 -> 3.9 | L9: 3 | M9: 1 | N9: =Calcutta!I36 -> 4060 | O9: =Calcutta!J36 -> 0 | P9: =Calcutta!K36 -> #N/A | S9: 1 | T9: Saturday | U9: 1 | V9: =Calcutta!$N$14 -> 1120 | W9: =Calcutta!S14 -> Paschke, Michael | X9: =Calcutta!T14 -> Edwards, Patric
A10: ='Master Player List'!L10 -> 1 | B10: ='Master Player List'!M10 -> 8 | C10: ='Master Player List'!C10 -> Black, Gene | D10: ='Master Player List'!F10 -> Tilson, Scott | E10: ='Master Player List'!N10 -> Vidrine, Scot | F10: =Calcutta!E18 -> 3000 | G10: ='Master Player List'!J10 -> 4.5 | H10: ='Master Player List'!E10 -> 3.1 | I10: ='Master Player List'!H10 -> 1.4 | L10: 3 | M10: 2 | N10: =Calcutta!I37 -> 2435 | O10: =Calcutta!J37 -> Hill, Justin | P10: =Calcutta!K37 -> Vidrine, Scot | S10: 1 | T10: Saturday | U10: 2 | V10: =Calcutta!$N$15 -> 670 | W10: =Calcutta!S15 -> Kim, Steven | X10: =Calcutta!T15 -> Godhania, Vikas
A11: ='Master Player List'!L11 -> 2 | B11: ='Master Player List'!M11 -> 1 | C11: ='Master Player List'!C11 -> Lau, Jason | D11: ='Master Player List'!F11 -> Martin, Aaron | E11: ='Master Player List'!N11 -> Brymer, Cory | F11: =Calcutta!E22 -> 2600 | G11: ='Master Player List'!J11 -> 4.6 | H11: ='Master Player List'!E11 -> 4.7 | I11: ='Master Player List'!H11 -> +0.1 | L11: 3 | M11: 3 | N11: =Calcutta!I38 -> 1625 | O11: =Calcutta!J38 -> 0 | P11: =Calcutta!K38 -> #N/A | S11: 1 | T11: Saturday | U11: 3 | V11: =Calcutta!$N$16 -> 445 | W11: =Calcutta!S16 -> Paschke, Michael | X11: =Calcutta!T16 -> Edwards, Patric
A12: ='Master Player List'!L12 -> 2 | B12: ='Master Player List'!M12 -> 2 | C12: ='Master Player List'!C12 -> Peterson, Erik | D12: ='Master Player List'!F12 -> Ferrell, Ryan | E12: ='Master Player List'!N12 -> Aghazadeh, Abdol | F12: =Calcutta!E23 -> 2200 | G12: ='Master Player List'!J12 -> 5 | H12: ='Master Player List'!E12 -> 0 | I12: ='Master Player List'!H12 -> 5 | L12: 4 | M12: 1 | N12: =Calcutta!I47 -> 5925 | O12: =Calcutta!J47 -> Dietz, Jeffrey | P12: =Calcutta!K47 -> Aghazadeh, Abdol | S12: 2 | T12: Thursday | U12: 1 | V12: =Calcutta!$N$25 -> 1145 | W12: =Calcutta!O25 -> Escobar, Rafael | X12: =Calcutta!P25 -> Bohnen, John
A13: ='Master Player List'!L13 -> 2 | B13: ='Master Player List'!M13 -> 3 | C13: ='Master Player List'!C13 -> Fulmer, Austen | D13: ='Master Player List'!F13 -> Pacheco, Jeremy | E13: ='Master Player List'!N13 -> Aghazadeh, Abdol | F13: =Calcutta!E24 -> 2800 | G13: ='Master Player List'!J13 -> 5.1 | H13: ='Master Player List'!E13 -> +3.4 | I13: ='Master Player List'!H13 -> 8.5 | L13: 4 | M13: 2 | N13: =Calcutta!I48 -> 3555 | O13: =Calcutta!J48 -> Tionloc, Alex | P13: =Calcutta!K48 -> Vidrine, Scot | S13: 2 | T13: Thursday | U13: 2 | V13: =Calcutta!$N$26 -> 685 | W13: =Calcutta!O26 -> Sherman, Michael | X13: =Calcutta!P26 -> Brymer, Cory
A14: ='Master Player List'!L14 -> 2 | B14: ='Master Player List'!M14 -> 4 | C14: ='Master Player List'!C14 -> Escobar, Rafael | D14: ='Master Player List'!F14 -> Gillmor, Rob | E14: ='Master Player List'!N14 -> Bohnen, John | F14: =Calcutta!E25 -> 1800 | G14: ='Master Player List'!J14 -> 6 | H14: ='Master Player List'!E14 -> 1.5 | I14: ='Master Player List'!H14 -> 4.5 | L14: 4 | M14: 3 | N14: =Calcutta!I49 -> 2370 | O14: =Calcutta!J49 -> Redding, Scott | P14: =Calcutta!K49 -> Vaughn, Earl | S14: 2 | T14: Thursday | U14: 3 | V14: =Calcutta!$N$27 -> 455 | W14: =Calcutta!O27 -> Peterson, Erik | X14: =Calcutta!P27 -> Aghazadeh, Abdol
